[2024-09-01 10:12:36 -0400] [70400] [ERROR] Exception in ASGI application
Traceback (most recent call last):
  File "/var/www/html/fastapi_project/venv/lib/python3.12/site-packages/uvicorn/protocols/http/httptools_impl.py", line 401, in run_asgi
    result = await app(  # type: ignore[func-returns-value]
             ^^^^^^^^^^^^^^^^^^^^^^^^^^^^^^^^^^^^^^^^^^^^^^
  File "/var/www/html/fastapi_project/venv/lib/python3.12/site-packages/uvicorn/middleware/proxy_headers.py", line 70, in __call__
    return await self.app(scope, receive, send)
           ^^^^^^^^^^^^^^^^^^^^^^^^^^^^^^^^^^^^
  File "/var/www/html/fastapi_project/venv/lib/python3.12/site-packages/fastapi/applications.py", line 1054, in __call__
    await super().__call__(scope, receive, send)
  File "/var/www/html/fastapi_project/venv/lib/python3.12/site-packages/starlette/applications.py", line 123, in __call__
    await self.middleware_stack(scope, receive, send)
  File "/var/www/html/fastapi_project/venv/lib/python3.12/site-packages/starlette/middleware/errors.py", line 186, in __call__
    raise exc
  File "/var/www/html/fastapi_project/venv/lib/python3.12/site-packages/starlette/middleware/errors.py", line 164, in __call__
    await self.app(scope, receive, _send)
  File "/var/www/html/fastapi_project/venv/lib/python3.12/site-packages/starlette/middleware/exceptions.py", line 65, in __call__
    await wrap_app_handling_exceptions(self.app, conn)(scope, receive, send)
  File "/var/www/html/fastapi_project/venv/lib/python3.12/site-packages/starlette/_exception_handler.py", line 64, in wrapped_app
    raise exc
  File "/var/www/html/fastapi_project/venv/lib/python3.12/site-packages/starlette/_exception_handler.py", line 53, in wrapped_app
    await app(scope, receive, sender)
  File "/var/www/html/fastapi_project/venv/lib/python3.12/site-packages/starlette/routing.py", line 754, in __call__
    await self.middleware_stack(scope, receive, send)
  File "/var/www/html/fastapi_project/venv/lib/python3.12/site-packages/starlette/routing.py", line 774, in app
    await route.handle(scope, receive, send)
  File "/var/www/html/fastapi_project/venv/lib/python3.12/site-packages/starlette/routing.py", line 295, in handle
    await self.app(scope, receive, send)
  File "/var/www/html/fastapi_project/venv/lib/python3.12/site-packages/starlette/routing.py", line 77, in app
    await wrap_app_handling_exceptions(app, request)(scope, receive, send)
  File "/var/www/html/fastapi_project/venv/lib/python3.12/site-packages/starlette/_exception_handler.py", line 64, in wrapped_app
    raise exc
  File "/var/www/html/fastapi_project/venv/lib/python3.12/site-packages/starlette/_exception_handler.py", line 53, in wrapped_app
    await app(scope, receive, sender)
  File "/var/www/html/fastapi_project/venv/lib/python3.12/site-packages/starlette/routing.py", line 75, in app
    await response(scope, receive, send)
  File "/var/www/html/fastapi_project/venv/lib/python3.12/site-packages/starlette/responses.py", line 162, in __call__
    await self.background()
  File "/var/www/html/fastapi_project/venv/lib/python3.12/site-packages/starlette/background.py", line 45, in __call__
    await task()
  File "/var/www/html/fastapi_project/venv/lib/python3.12/site-packages/starlette/background.py", line 30, in __call__
    await run_in_threadpool(self.func, *self.args, **self.kwargs)
  File "/var/www/html/fastapi_project/venv/lib/python3.12/site-packages/starlette/concurrency.py", line 42, in run_in_threadpool
    return await anyio.to_thread.run_sync(func, *args)
           ^^^^^^^^^^^^^^^^^^^^^^^^^^^^^^^^^^^^^^^^^^^
  File "/var/www/html/fastapi_project/venv/lib/python3.12/site-packages/anyio/to_thread.py", line 56, in run_sync
    return await get_async_backend().run_sync_in_worker_thread(
           ^^^^^^^^^^^^^^^^^^^^^^^^^^^^^^^^^^^^^^^^^^^^^^^^^^^^
  File "/var/www/html/fastapi_project/venv/lib/python3.12/site-packages/anyio/_backends/_asyncio.py", line 2177, in run_sync_in_worker_thread
    return await future
           ^^^^^^^^^^^^
  File "/var/www/html/fastapi_project/venv/lib/python3.12/site-packages/anyio/_backends/_asyncio.py", line 859, in run
    result = context.run(func, *args)
             ^^^^^^^^^^^^^^^^^^^^^^^^
  File "/var/www/html/fastapi_project/start_files/routes/routes.py", line 377, in <lambda>
    background_tasks.add_task(lambda: asyncio.create_task(gather_images_and_mls_data(max_price)))
                                      ^^^^^^^^^^^^^^^^^^^^^^^^^^^^^^^^^^^^^^^^^^^^^^^^^^^^^^^^^^
  File "/usr/lib/python3.12/asyncio/tasks.py", line 417, in create_task
    loop = events.get_running_loop()
           ^^^^^^^^^^^^^^^^^^^^^^^^^
RuntimeError: no running event loop
[2024-09-01 10:13:42 -0400] [70371] [INFO] Handling signal: term
[2024-09-01 10:13:42 -0400] [70401] [INFO] Shutting down
[2024-09-01 10:13:42 -0400] [70401] [INFO] Error while closing socket [Errno 9] Bad file descriptor
[2024-09-01 10:13:42 -0400] [70400] [INFO] Shutting down
[2024-09-01 10:13:42 -0400] [70398] [INFO] Shutting down
[2024-09-01 10:13:42 -0400] [70400] [INFO] Error while closing socket [Errno 9] Bad file descriptor
[2024-09-01 10:13:42 -0400] [70398] [INFO] Error while closing socket [Errno 9] Bad file descriptor
[2024-09-01 10:13:42 -0400] [70399] [INFO] Shutting down
[2024-09-01 10:13:42 -0400] [70399] [INFO] Error while closing socket [Errno 9] Bad file descriptor
[2024-09-01 10:13:42 -0400] [70401] [INFO] Waiting for application shutdown.
[2024-09-01 10:13:42 -0400] [70401] [INFO] Application shutdown complete.
[2024-09-01 10:13:42 -0400] [70401] [INFO] Finished server process [70401]
[2024-09-01 10:13:42 -0400] [70371] [ERROR] Worker (pid:70401) was sent SIGTERM!
[2024-09-01 10:13:42 -0400] [70398] [INFO] Waiting for application shutdown.
[2024-09-01 10:13:42 -0400] [70400] [INFO] Waiting for application shutdown.
[2024-09-01 10:13:42 -0400] [70398] [INFO] Application shutdown complete.
[2024-09-01 10:13:42 -0400] [70398] [INFO] Finished server process [70398]
[2024-09-01 10:13:42 -0400] [70400] [INFO] Application shutdown complete.
[2024-09-01 10:13:42 -0400] [70400] [INFO] Finished server process [70400]
[2024-09-01 10:13:42 -0400] [70399] [INFO] Waiting for application shutdown.
[2024-09-01 10:13:42 -0400] [70399] [INFO] Application shutdown complete.
[2024-09-01 10:13:42 -0400] [70399] [INFO] Finished server process [70399]
[2024-09-01 10:13:42 -0400] [70371] [ERROR] Worker (pid:70398) was sent SIGTERM!
[2024-09-01 10:13:42 -0400] [70371] [ERROR] Worker (pid:70400) was sent SIGTERM!
[2024-09-01 10:13:42 -0400] [70371] [ERROR] Worker (pid:70399) was sent SIGTERM!
[2024-09-01 10:13:43 -0400] [70371] [INFO] Shutting down: Master
[2024-09-01 10:14:20 -0400] [71457] [INFO] Starting gunicorn 23.0.0
[2024-09-01 10:14:20 -0400] [71457] [INFO] Listening at: http://192.168.0.100:5000 (71457)
[2024-09-01 10:14:20 -0400] [71457] [INFO] Using worker: uvicorn.workers.UvicornWorker
[2024-09-01 10:14:20 -0400] [71462] [INFO] Booting worker with pid: 71462
[2024-09-01 10:14:20 -0400] [71463] [INFO] Booting worker with pid: 71463
[2024-09-01 10:14:20 -0400] [71464] [INFO] Booting worker with pid: 71464
[2024-09-01 10:14:20 -0400] [71465] [INFO] Booting worker with pid: 71465
[2024-09-01 10:14:25 -0400] [71462] [INFO] Started server process [71462]
[2024-09-01 10:14:25 -0400] [71462] [INFO] Waiting for application startup.
[2024-09-01 10:14:25 -0400] [71462] [INFO] Application startup complete.
[2024-09-01 10:14:25 -0400] [71464] [INFO] Started server process [71464]
[2024-09-01 10:14:25 -0400] [71464] [INFO] Waiting for application startup.
[2024-09-01 10:14:25 -0400] [71464] [INFO] Application startup complete.
[2024-09-01 10:14:25 -0400] [71463] [INFO] Started server process [71463]
[2024-09-01 10:14:25 -0400] [71463] [INFO] Waiting for application startup.
[2024-09-01 10:14:25 -0400] [71463] [INFO] Application startup complete.
[2024-09-01 10:14:25 -0400] [71465] [INFO] Started server process [71465]
[2024-09-01 10:14:25 -0400] [71465] [INFO] Waiting for application startup.
[2024-09-01 10:14:25 -0400] [71465] [INFO] Application startup complete.
[2024-09-01 10:15:08 -0400] [71465] [ERROR] Exception in ASGI application
Traceback (most recent call last):
  File "/var/www/html/fastapi_project/start_files/routes/routes.py", line 145, in export_results
    WebDriverWait(driver, timeout).until(element_present)
  File "/var/www/html/fastapi_project/venv/lib/python3.12/site-packages/selenium/webdriver/support/wait.py", line 96, in until
    value = method(self._driver)
            ^^^^^^^^^^^^^^^^^^^^
  File "/var/www/html/fastapi_project/venv/lib/python3.12/site-packages/selenium/webdriver/support/expected_conditions.py", line 364, in _predicate
    element = visibility_of(target)(driver)
              ^^^^^^^^^^^^^^^^^^^^^^^^^^^^^
  File "/var/www/html/fastapi_project/venv/lib/python3.12/site-packages/selenium/webdriver/support/expected_conditions.py", line 173, in _predicate
    return _element_if_visible(element)
           ^^^^^^^^^^^^^^^^^^^^^^^^^^^^
  File "/var/www/html/fastapi_project/venv/lib/python3.12/site-packages/selenium/webdriver/support/expected_conditions.py", line 179, in _element_if_visible
    return element if element.is_displayed() == visibility else False
                      ^^^^^^^^^^^^^^^^^^^^^^
  File "/var/www/html/fastapi_project/venv/lib/python3.12/site-packages/selenium/webdriver/remote/webelement.py", line 252, in is_displayed
    return self.parent.execute_script(f"/* isDisplayed */return ({isDisplayed_js}).apply(null, arguments);", self)
           ^^^^^^^^^^^^^^^^^^^^^^^^^^^^^^^^^^^^^^^^^^^^^^^^^^^^^^^^^^^^^^^^^^^^^^^^^^^^^^^^^^^^^^^^^^^^^^^^^^^^^^^
  File "/var/www/html/fastapi_project/venv/lib/python3.12/site-packages/selenium/webdriver/remote/webdriver.py", line 414, in execute_script
    return self.execute(command, {"script": script, "args": converted_args})["value"]
           ^^^^^^^^^^^^^^^^^^^^^^^^^^^^^^^^^^^^^^^^^^^^^^^^^^^^^^^^^^^^^^^^^
  File "/var/www/html/fastapi_project/venv/lib/python3.12/site-packages/selenium/webdriver/remote/webdriver.py", line 354, in execute
    self.error_handler.check_response(response)
  File "/var/www/html/fastapi_project/venv/lib/python3.12/site-packages/selenium/webdriver/remote/errorhandler.py", line 229, in check_response
    raise exception_class(message, screen, stacktrace)
selenium.common.exceptions.StaleElementReferenceException: Message: stale element reference: stale element not found in the current frame
  (Session info: chrome-headless-shell=126.0.6478.126); For documentation on this error, please visit: https://www.selenium.dev/documentation/webdriver/troubleshooting/errors#stale-element-reference-exception
Stacktrace:
#0 0xaaaadf7d53a8 <unknown>
#1 0xaaaadf4ffb24 <unknown>
#2 0xaaaadf5046f0 <unknown>
#3 0xaaaadf506288 <unknown>
#4 0xaaaadf57bd84 <unknown>
#5 0xaaaadf57b2e8 <unknown>
#6 0xaaaadf536a80 <unknown>
#7 0xaaaadf53745c <unknown>
#8 0xaaaadf7a0b18 <unknown>
#9 0xaaaadf7a4124 <unknown>
#10 0xaaaadf78f894 <unknown>
#11 0xaaaadf7a47c4 <unknown>
#12 0xaaaadf777df4 <unknown>
#13 0xaaaadf7c5280 <unknown>
#14 0xaaaadf7c5450 <unknown>
#15 0xaaaadf7d44f0 <unknown>
#16 0xffff8477597c <unknown>
#17 0xffff847dba4c <unknown>


During handling of the above exception, another exception occurred:

Traceback (most recent call last):
  File "/var/www/html/fastapi_project/venv/lib/python3.12/site-packages/starlette/_exception_handler.py", line 53, in wrapped_app
    await app(scope, receive, sender)
  File "/var/www/html/fastapi_project/venv/lib/python3.12/site-packages/starlette/routing.py", line 75, in app
    await response(scope, receive, send)
  File "/var/www/html/fastapi_project/venv/lib/python3.12/site-packages/starlette/responses.py", line 162, in __call__
    await self.background()
  File "/var/www/html/fastapi_project/venv/lib/python3.12/site-packages/starlette/background.py", line 45, in __call__
    await task()
  File "/var/www/html/fastapi_project/venv/lib/python3.12/site-packages/starlette/background.py", line 30, in __call__
    await run_in_threadpool(self.func, *self.args, **self.kwargs)
  File "/var/www/html/fastapi_project/venv/lib/python3.12/site-packages/starlette/concurrency.py", line 42, in run_in_threadpool
    return await anyio.to_thread.run_sync(func, *args)
           ^^^^^^^^^^^^^^^^^^^^^^^^^^^^^^^^^^^^^^^^^^^
  File "/var/www/html/fastapi_project/venv/lib/python3.12/site-packages/anyio/to_thread.py", line 56, in run_sync
    return await get_async_backend().run_sync_in_worker_thread(
           ^^^^^^^^^^^^^^^^^^^^^^^^^^^^^^^^^^^^^^^^^^^^^^^^^^^^
  File "/var/www/html/fastapi_project/venv/lib/python3.12/site-packages/anyio/_backends/_asyncio.py", line 2177, in run_sync_in_worker_thread
    return await future
           ^^^^^^^^^^^^
  File "/var/www/html/fastapi_project/venv/lib/python3.12/site-packages/anyio/_backends/_asyncio.py", line 859, in run
    result = context.run(func, *args)
             ^^^^^^^^^^^^^^^^^^^^^^^^
  File "/var/www/html/fastapi_project/start_files/routes/routes.py", line 280, in sync_gather_images_and_mls_data
    loop.run_until_complete(gather_images_and_mls_data(max_price))
  File "uvloop/loop.pyx", line 1517, in uvloop.loop.Loop.run_until_complete
  File "/var/www/html/fastapi_project/start_files/routes/routes.py", line 290, in gather_images_and_mls_data
    await export_results()
  File "/var/www/html/fastapi_project/start_files/routes/routes.py", line 181, in export_results
    raise HTTPException(status_code=500, detail="Error during export results")
fastapi.exceptions.HTTPException: 500: Error during export results

The above exception was the direct cause of the following exception:

Traceback (most recent call last):
  File "/var/www/html/fastapi_project/venv/lib/python3.12/site-packages/uvicorn/protocols/http/httptools_impl.py", line 401, in run_asgi
    result = await app(  # type: ignore[func-returns-value]
             ^^^^^^^^^^^^^^^^^^^^^^^^^^^^^^^^^^^^^^^^^^^^^^
  File "/var/www/html/fastapi_project/venv/lib/python3.12/site-packages/uvicorn/middleware/proxy_headers.py", line 70, in __call__
    return await self.app(scope, receive, send)
           ^^^^^^^^^^^^^^^^^^^^^^^^^^^^^^^^^^^^
  File "/var/www/html/fastapi_project/venv/lib/python3.12/site-packages/fastapi/applications.py", line 1054, in __call__
    await super().__call__(scope, receive, send)
  File "/var/www/html/fastapi_project/venv/lib/python3.12/site-packages/starlette/applications.py", line 123, in __call__
    await self.middleware_stack(scope, receive, send)
  File "/var/www/html/fastapi_project/venv/lib/python3.12/site-packages/starlette/middleware/errors.py", line 186, in __call__
    raise exc
  File "/var/www/html/fastapi_project/venv/lib/python3.12/site-packages/starlette/middleware/errors.py", line 164, in __call__
    await self.app(scope, receive, _send)
  File "/var/www/html/fastapi_project/venv/lib/python3.12/site-packages/starlette/middleware/exceptions.py", line 65, in __call__
    await wrap_app_handling_exceptions(self.app, conn)(scope, receive, send)
  File "/var/www/html/fastapi_project/venv/lib/python3.12/site-packages/starlette/_exception_handler.py", line 64, in wrapped_app
    raise exc
  File "/var/www/html/fastapi_project/venv/lib/python3.12/site-packages/starlette/_exception_handler.py", line 53, in wrapped_app
    await app(scope, receive, sender)
  File "/var/www/html/fastapi_project/venv/lib/python3.12/site-packages/starlette/routing.py", line 754, in __call__
    await self.middleware_stack(scope, receive, send)
  File "/var/www/html/fastapi_project/venv/lib/python3.12/site-packages/starlette/routing.py", line 774, in app
    await route.handle(scope, receive, send)
  File "/var/www/html/fastapi_project/venv/lib/python3.12/site-packages/starlette/routing.py", line 295, in handle
    await self.app(scope, receive, send)
  File "/var/www/html/fastapi_project/venv/lib/python3.12/site-packages/starlette/routing.py", line 77, in app
    await wrap_app_handling_exceptions(app, request)(scope, receive, send)
  File "/var/www/html/fastapi_project/venv/lib/python3.12/site-packages/starlette/_exception_handler.py", line 68, in wrapped_app
    raise RuntimeError(msg) from exc
RuntimeError: Caught handled exception, but response already started.
[2024-09-01 10:17:18 -0400] [71457] [INFO] Handling signal: term
[2024-09-01 10:17:18 -0400] [71462] [INFO] Shutting down
[2024-09-01 10:17:18 -0400] [71463] [INFO] Shutting down
[2024-09-01 10:17:18 -0400] [71464] [INFO] Shutting down
[2024-09-01 10:17:18 -0400] [71463] [INFO] Error while closing socket [Errno 9] Bad file descriptor
[2024-09-01 10:17:18 -0400] [71462] [INFO] Error while closing socket [Errno 9] Bad file descriptor
[2024-09-01 10:17:18 -0400] [71464] [INFO] Error while closing socket [Errno 9] Bad file descriptor
[2024-09-01 10:17:18 -0400] [71465] [INFO] Shutting down
[2024-09-01 10:17:18 -0400] [71465] [INFO] Error while closing socket [Errno 9] Bad file descriptor
[2024-09-01 10:17:18 -0400] [71464] [INFO] Waiting for application shutdown.
[2024-09-01 10:17:18 -0400] [71463] [INFO] Waiting for application shutdown.
[2024-09-01 10:17:18 -0400] [71464] [INFO] Application shutdown complete.
[2024-09-01 10:17:18 -0400] [71463] [INFO] Application shutdown complete.
[2024-09-01 10:17:18 -0400] [71462] [INFO] Waiting for application shutdown.
[2024-09-01 10:17:18 -0400] [71464] [INFO] Finished server process [71464]
[2024-09-01 10:17:18 -0400] [71463] [INFO] Finished server process [71463]
[2024-09-01 10:17:18 -0400] [71462] [INFO] Application shutdown complete.
[2024-09-01 10:17:18 -0400] [71462] [INFO] Finished server process [71462]
[2024-09-01 10:17:18 -0400] [71465] [INFO] Waiting for application shutdown.
[2024-09-01 10:17:18 -0400] [71465] [INFO] Application shutdown complete.
[2024-09-01 10:17:18 -0400] [71465] [INFO] Finished server process [71465]
[2024-09-01 10:17:19 -0400] [71457] [ERROR] Worker (pid:71464) was sent SIGTERM!
[2024-09-01 10:17:19 -0400] [71457] [ERROR] Worker (pid:71465) was sent SIGTERM!
[2024-09-01 10:17:19 -0400] [71457] [ERROR] Worker (pid:71462) was sent SIGTERM!
[2024-09-01 10:17:19 -0400] [71457] [ERROR] Worker (pid:71463) was sent SIGTERM!
[2024-09-01 10:17:19 -0400] [71457] [INFO] Shutting down: Master
[2024-09-01 10:17:21 -0400] [72696] [INFO] Starting gunicorn 23.0.0
[2024-09-01 10:17:21 -0400] [72696] [INFO] Listening at: http://192.168.0.100:5000 (72696)
[2024-09-01 10:17:21 -0400] [72696] [INFO] Using worker: uvicorn.workers.UvicornWorker
[2024-09-01 10:17:21 -0400] [72702] [INFO] Booting worker with pid: 72702
[2024-09-01 10:17:21 -0400] [72703] [INFO] Booting worker with pid: 72703
[2024-09-01 10:17:21 -0400] [72707] [INFO] Booting worker with pid: 72707
[2024-09-01 10:17:21 -0400] [72710] [INFO] Booting worker with pid: 72710
[2024-09-01 10:17:25 -0400] [72703] [INFO] Started server process [72703]
[2024-09-01 10:17:25 -0400] [72703] [INFO] Waiting for application startup.
[2024-09-01 10:17:25 -0400] [72703] [INFO] Application startup complete.
[2024-09-01 10:17:25 -0400] [72702] [INFO] Started server process [72702]
[2024-09-01 10:17:25 -0400] [72702] [INFO] Waiting for application startup.
[2024-09-01 10:17:25 -0400] [72702] [INFO] Application startup complete.
[2024-09-01 10:17:25 -0400] [72707] [INFO] Started server process [72707]
[2024-09-01 10:17:25 -0400] [72707] [INFO] Waiting for application startup.
[2024-09-01 10:17:25 -0400] [72707] [INFO] Application startup complete.
[2024-09-01 10:17:25 -0400] [72710] [INFO] Started server process [72710]
[2024-09-01 10:17:25 -0400] [72710] [INFO] Waiting for application startup.
[2024-09-01 10:17:25 -0400] [72710] [INFO] Application startup complete.
[2024-09-01 12:04:42 -0400] [72703] [WARNING] Invalid HTTP request received.
[2024-09-01 12:53:48 -0400] [72703] [WARNING] Invalid HTTP request received.
