[2024-08-22 09:43:42 -0400] [23542] [INFO] Starting gunicorn 23.0.0
[2024-08-22 09:43:42 -0400] [23542] [INFO] Listening at: http://0.0.0.0:5000 (23542)
[2024-08-22 09:43:42 -0400] [23542] [INFO] Using worker: uvicorn.workers.UvicornWorker
[2024-08-22 09:43:42 -0400] [23543] [INFO] Booting worker with pid: 23543
[2024-08-22 09:43:42 -0400] [23544] [INFO] Booting worker with pid: 23544
[2024-08-22 09:43:42 -0400] [23545] [INFO] Booting worker with pid: 23545
[2024-08-22 09:43:42 -0400] [23546] [INFO] Booting worker with pid: 23546
[2024-08-22 09:43:44 -0400] [23543] [ERROR] Exception in worker process
Traceback (most recent call last):
  File "/home/oyone/fastapi_project/venv/lib/python3.12/site-packages/gunicorn/arbiter.py", line 608, in spawn_worker
    worker.init_process()
  File "/home/oyone/fastapi_project/venv/lib/python3.12/site-packages/uvicorn/workers.py", line 75, in init_process
    super().init_process()
  File "/home/oyone/fastapi_project/venv/lib/python3.12/site-packages/gunicorn/workers/base.py", line 135, in init_process
    self.load_wsgi()
  File "/home/oyone/fastapi_project/venv/lib/python3.12/site-packages/gunicorn/workers/base.py", line 147, in load_wsgi
    self.wsgi = self.app.wsgi()
                ^^^^^^^^^^^^^^^
  File "/home/oyone/fastapi_project/venv/lib/python3.12/site-packages/gunicorn/app/base.py", line 66, in wsgi
    self.callable = self.load()
                    ^^^^^^^^^^^
  File "/home/oyone/fastapi_project/venv/lib/python3.12/site-packages/gunicorn/app/wsgiapp.py", line 57, in load
    return self.load_wsgiapp()
           ^^^^^^^^^^^^^^^^^^^
  File "/home/oyone/fastapi_project/venv/lib/python3.12/site-packages/gunicorn/app/wsgiapp.py", line 47, in load_wsgiapp
    return util.import_app(self.app_uri)
           ^^^^^^^^^^^^^^^^^^^^^^^^^^^^^
  File "/home/oyone/fastapi_project/venv/lib/python3.12/site-packages/gunicorn/util.py", line 370, in import_app
    mod = importlib.import_module(module)
          ^^^^^^^^^^^^^^^^^^^^^^^^^^^^^^^
  File "/usr/lib/python3.12/importlib/__init__.py", line 90, in import_module
    return _bootstrap._gcd_import(name[level:], package, level)
           ^^^^^^^^^^^^^^^^^^^^^^^^^^^^^^^^^^^^^^^^^^^^^^^^^^^^
  File "<frozen importlib._bootstrap>", line 1387, in _gcd_import
  File "<frozen importlib._bootstrap>", line 1360, in _find_and_load
  File "<frozen importlib._bootstrap>", line 1331, in _find_and_load_unlocked
  File "<frozen importlib._bootstrap>", line 935, in _load_unlocked
  File "<frozen importlib._bootstrap_external>", line 995, in exec_module
  File "<frozen importlib._bootstrap>", line 488, in _call_with_frames_removed
  File "/home/oyone/fastapi_project/main.py", line 3, in <module>
    app = create_app()
          ^^^^^^^^^^^^
  File "/home/oyone/fastapi_project/start_files/app.py", line 13, in create_app
    templates = get_templates()
                ^^^^^^^^^^^^^^^
  File "/home/oyone/fastapi_project/start_files/config.py", line 24, in get_templates
    return Jinja2Templates(directory="start_files/templates")
           ^^^^^^^^^^^^^^^^^^^^^^^^^^^^^^^^^^^^^^^^^^^^^^^^^^
  File "/home/oyone/fastapi_project/venv/lib/python3.12/site-packages/starlette/templating.py", line 102, in __init__
    assert jinja2 is not None, "jinja2 must be installed to use Jinja2Templates"
           ^^^^^^^^^^^^^^^^^^
AssertionError: jinja2 must be installed to use Jinja2Templates
[2024-08-22 09:43:44 -0400] [23543] [INFO] Worker exiting (pid: 23543)
[2024-08-22 09:43:45 -0400] [23544] [ERROR] Exception in worker process
Traceback (most recent call last):
  File "/home/oyone/fastapi_project/venv/lib/python3.12/site-packages/gunicorn/arbiter.py", line 608, in spawn_worker
    worker.init_process()
  File "/home/oyone/fastapi_project/venv/lib/python3.12/site-packages/uvicorn/workers.py", line 75, in init_process
    super().init_process()
  File "/home/oyone/fastapi_project/venv/lib/python3.12/site-packages/gunicorn/workers/base.py", line 135, in init_process
    self.load_wsgi()
  File "/home/oyone/fastapi_project/venv/lib/python3.12/site-packages/gunicorn/workers/base.py", line 147, in load_wsgi
    self.wsgi = self.app.wsgi()
                ^^^^^^^^^^^^^^^
  File "/home/oyone/fastapi_project/venv/lib/python3.12/site-packages/gunicorn/app/base.py", line 66, in wsgi
    self.callable = self.load()
                    ^^^^^^^^^^^
  File "/home/oyone/fastapi_project/venv/lib/python3.12/site-packages/gunicorn/app/wsgiapp.py", line 57, in load
    return self.load_wsgiapp()
           ^^^^^^^^^^^^^^^^^^^
  File "/home/oyone/fastapi_project/venv/lib/python3.12/site-packages/gunicorn/app/wsgiapp.py", line 47, in load_wsgiapp
    return util.import_app(self.app_uri)
           ^^^^^^^^^^^^^^^^^^^^^^^^^^^^^
  File "/home/oyone/fastapi_project/venv/lib/python3.12/site-packages/gunicorn/util.py", line 370, in import_app
    mod = importlib.import_module(module)
          ^^^^^^^^^^^^^^^^^^^^^^^^^^^^^^^
  File "/usr/lib/python3.12/importlib/__init__.py", line 90, in import_module
    return _bootstrap._gcd_import(name[level:], package, level)
           ^^^^^^^^^^^^^^^^^^^^^^^^^^^^^^^^^^^^^^^^^^^^^^^^^^^^
  File "<frozen importlib._bootstrap>", line 1387, in _gcd_import
  File "<frozen importlib._bootstrap>", line 1360, in _find_and_load
  File "<frozen importlib._bootstrap>", line 1331, in _find_and_load_unlocked
  File "<frozen importlib._bootstrap>", line 935, in _load_unlocked
  File "<frozen importlib._bootstrap_external>", line 995, in exec_module
  File "<frozen importlib._bootstrap>", line 488, in _call_with_frames_removed
  File "/home/oyone/fastapi_project/main.py", line 3, in <module>
    app = create_app()
          ^^^^^^^^^^^^
  File "/home/oyone/fastapi_project/start_files/app.py", line 13, in create_app
    templates = get_templates()
                ^^^^^^^^^^^^^^^
  File "/home/oyone/fastapi_project/start_files/config.py", line 24, in get_templates
    return Jinja2Templates(directory="start_files/templates")
           ^^^^^^^^^^^^^^^^^^^^^^^^^^^^^^^^^^^^^^^^^^^^^^^^^^
  File "/home/oyone/fastapi_project/venv/lib/python3.12/site-packages/starlette/templating.py", line 102, in __init__
    assert jinja2 is not None, "jinja2 must be installed to use Jinja2Templates"
           ^^^^^^^^^^^^^^^^^^
AssertionError: jinja2 must be installed to use Jinja2Templates
[2024-08-22 09:43:45 -0400] [23544] [INFO] Worker exiting (pid: 23544)
[2024-08-22 09:43:45 -0400] [23545] [ERROR] Exception in worker process
Traceback (most recent call last):
  File "/home/oyone/fastapi_project/venv/lib/python3.12/site-packages/gunicorn/arbiter.py", line 608, in spawn_worker
    worker.init_process()
  File "/home/oyone/fastapi_project/venv/lib/python3.12/site-packages/uvicorn/workers.py", line 75, in init_process
    super().init_process()
  File "/home/oyone/fastapi_project/venv/lib/python3.12/site-packages/gunicorn/workers/base.py", line 135, in init_process
    self.load_wsgi()
  File "/home/oyone/fastapi_project/venv/lib/python3.12/site-packages/gunicorn/workers/base.py", line 147, in load_wsgi
    self.wsgi = self.app.wsgi()
                ^^^^^^^^^^^^^^^
  File "/home/oyone/fastapi_project/venv/lib/python3.12/site-packages/gunicorn/app/base.py", line 66, in wsgi
    self.callable = self.load()
                    ^^^^^^^^^^^
  File "/home/oyone/fastapi_project/venv/lib/python3.12/site-packages/gunicorn/app/wsgiapp.py", line 57, in load
    return self.load_wsgiapp()
           ^^^^^^^^^^^^^^^^^^^
  File "/home/oyone/fastapi_project/venv/lib/python3.12/site-packages/gunicorn/app/wsgiapp.py", line 47, in load_wsgiapp
    return util.import_app(self.app_uri)
           ^^^^^^^^^^^^^^^^^^^^^^^^^^^^^
  File "/home/oyone/fastapi_project/venv/lib/python3.12/site-packages/gunicorn/util.py", line 370, in import_app
    mod = importlib.import_module(module)
          ^^^^^^^^^^^^^^^^^^^^^^^^^^^^^^^
  File "/usr/lib/python3.12/importlib/__init__.py", line 90, in import_module
    return _bootstrap._gcd_import(name[level:], package, level)
           ^^^^^^^^^^^^^^^^^^^^^^^^^^^^^^^^^^^^^^^^^^^^^^^^^^^^
  File "<frozen importlib._bootstrap>", line 1387, in _gcd_import
  File "<frozen importlib._bootstrap>", line 1360, in _find_and_load
  File "<frozen importlib._bootstrap>", line 1331, in _find_and_load_unlocked
  File "<frozen importlib._bootstrap>", line 935, in _load_unlocked
  File "<frozen importlib._bootstrap_external>", line 995, in exec_module
  File "<frozen importlib._bootstrap>", line 488, in _call_with_frames_removed
  File "/home/oyone/fastapi_project/main.py", line 3, in <module>
    app = create_app()
          ^^^^^^^^^^^^
  File "/home/oyone/fastapi_project/start_files/app.py", line 13, in create_app
    templates = get_templates()
                ^^^^^^^^^^^^^^^
  File "/home/oyone/fastapi_project/start_files/config.py", line 24, in get_templates
    return Jinja2Templates(directory="start_files/templates")
           ^^^^^^^^^^^^^^^^^^^^^^^^^^^^^^^^^^^^^^^^^^^^^^^^^^
  File "/home/oyone/fastapi_project/venv/lib/python3.12/site-packages/starlette/templating.py", line 102, in __init__
    assert jinja2 is not None, "jinja2 must be installed to use Jinja2Templates"
           ^^^^^^^^^^^^^^^^^^
AssertionError: jinja2 must be installed to use Jinja2Templates
[2024-08-22 09:43:45 -0400] [23545] [INFO] Worker exiting (pid: 23545)
[2024-08-22 09:43:45 -0400] [23546] [ERROR] Exception in worker process
Traceback (most recent call last):
  File "/home/oyone/fastapi_project/venv/lib/python3.12/site-packages/gunicorn/arbiter.py", line 608, in spawn_worker
    worker.init_process()
  File "/home/oyone/fastapi_project/venv/lib/python3.12/site-packages/uvicorn/workers.py", line 75, in init_process
    super().init_process()
  File "/home/oyone/fastapi_project/venv/lib/python3.12/site-packages/gunicorn/workers/base.py", line 135, in init_process
    self.load_wsgi()
  File "/home/oyone/fastapi_project/venv/lib/python3.12/site-packages/gunicorn/workers/base.py", line 147, in load_wsgi
    self.wsgi = self.app.wsgi()
                ^^^^^^^^^^^^^^^
  File "/home/oyone/fastapi_project/venv/lib/python3.12/site-packages/gunicorn/app/base.py", line 66, in wsgi
    self.callable = self.load()
                    ^^^^^^^^^^^
  File "/home/oyone/fastapi_project/venv/lib/python3.12/site-packages/gunicorn/app/wsgiapp.py", line 57, in load
    return self.load_wsgiapp()
           ^^^^^^^^^^^^^^^^^^^
  File "/home/oyone/fastapi_project/venv/lib/python3.12/site-packages/gunicorn/app/wsgiapp.py", line 47, in load_wsgiapp
    return util.import_app(self.app_uri)
           ^^^^^^^^^^^^^^^^^^^^^^^^^^^^^
  File "/home/oyone/fastapi_project/venv/lib/python3.12/site-packages/gunicorn/util.py", line 370, in import_app
    mod = importlib.import_module(module)
          ^^^^^^^^^^^^^^^^^^^^^^^^^^^^^^^
  File "/usr/lib/python3.12/importlib/__init__.py", line 90, in import_module
    return _bootstrap._gcd_import(name[level:], package, level)
           ^^^^^^^^^^^^^^^^^^^^^^^^^^^^^^^^^^^^^^^^^^^^^^^^^^^^
  File "<frozen importlib._bootstrap>", line 1387, in _gcd_import
  File "<frozen importlib._bootstrap>", line 1360, in _find_and_load
  File "<frozen importlib._bootstrap>", line 1331, in _find_and_load_unlocked
  File "<frozen importlib._bootstrap>", line 935, in _load_unlocked
  File "<frozen importlib._bootstrap_external>", line 995, in exec_module
  File "<frozen importlib._bootstrap>", line 488, in _call_with_frames_removed
  File "/home/oyone/fastapi_project/main.py", line 3, in <module>
    app = create_app()
          ^^^^^^^^^^^^
  File "/home/oyone/fastapi_project/start_files/app.py", line 13, in create_app
    templates = get_templates()
                ^^^^^^^^^^^^^^^
  File "/home/oyone/fastapi_project/start_files/config.py", line 24, in get_templates
    return Jinja2Templates(directory="start_files/templates")
           ^^^^^^^^^^^^^^^^^^^^^^^^^^^^^^^^^^^^^^^^^^^^^^^^^^
  File "/home/oyone/fastapi_project/venv/lib/python3.12/site-packages/starlette/templating.py", line 102, in __init__
    assert jinja2 is not None, "jinja2 must be installed to use Jinja2Templates"
           ^^^^^^^^^^^^^^^^^^
AssertionError: jinja2 must be installed to use Jinja2Templates
[2024-08-22 09:43:45 -0400] [23546] [INFO] Worker exiting (pid: 23546)
[2024-08-22 09:43:45 -0400] [23542] [ERROR] Worker (pid:23543) exited with code 3
[2024-08-22 09:43:45 -0400] [23542] [ERROR] Worker (pid:23544) was sent SIGTERM!
[2024-08-22 09:43:45 -0400] [23542] [ERROR] Worker (pid:23545) was sent SIGTERM!
[2024-08-22 09:43:45 -0400] [23542] [ERROR] Worker (pid:23546) was sent SIGTERM!
[2024-08-22 09:43:45 -0400] [23542] [ERROR] Shutting down: Master
[2024-08-22 09:43:45 -0400] [23542] [ERROR] Reason: Worker failed to boot.
[2024-08-22 09:43:53 -0400] [23550] [INFO] Starting gunicorn 23.0.0
[2024-08-22 09:43:53 -0400] [23550] [INFO] Listening at: http://0.0.0.0:5000 (23550)
[2024-08-22 09:43:53 -0400] [23550] [INFO] Using worker: uvicorn.workers.UvicornWorker
[2024-08-22 09:43:53 -0400] [23551] [INFO] Booting worker with pid: 23551
[2024-08-22 09:43:53 -0400] [23552] [INFO] Booting worker with pid: 23552
[2024-08-22 09:43:53 -0400] [23553] [INFO] Booting worker with pid: 23553
[2024-08-22 09:43:53 -0400] [23554] [INFO] Booting worker with pid: 23554
[2024-08-22 09:43:56 -0400] [23551] [ERROR] Exception in worker process
Traceback (most recent call last):
  File "/home/oyone/fastapi_project/venv/lib/python3.12/site-packages/gunicorn/arbiter.py", line 608, in spawn_worker
    worker.init_process()
  File "/home/oyone/fastapi_project/venv/lib/python3.12/site-packages/uvicorn/workers.py", line 75, in init_process
    super().init_process()
  File "/home/oyone/fastapi_project/venv/lib/python3.12/site-packages/gunicorn/workers/base.py", line 135, in init_process
    self.load_wsgi()
  File "/home/oyone/fastapi_project/venv/lib/python3.12/site-packages/gunicorn/workers/base.py", line 147, in load_wsgi
    self.wsgi = self.app.wsgi()
                ^^^^^^^^^^^^^^^
  File "/home/oyone/fastapi_project/venv/lib/python3.12/site-packages/gunicorn/app/base.py", line 66, in wsgi
    self.callable = self.load()
                    ^^^^^^^^^^^
  File "/home/oyone/fastapi_project/venv/lib/python3.12/site-packages/gunicorn/app/wsgiapp.py", line 57, in load
    return self.load_wsgiapp()
           ^^^^^^^^^^^^^^^^^^^
  File "/home/oyone/fastapi_project/venv/lib/python3.12/site-packages/gunicorn/app/wsgiapp.py", line 47, in load_wsgiapp
    return util.import_app(self.app_uri)
           ^^^^^^^^^^^^^^^^^^^^^^^^^^^^^
  File "/home/oyone/fastapi_project/venv/lib/python3.12/site-packages/gunicorn/util.py", line 370, in import_app
    mod = importlib.import_module(module)
          ^^^^^^^^^^^^^^^^^^^^^^^^^^^^^^^
  File "/usr/lib/python3.12/importlib/__init__.py", line 90, in import_module
    return _bootstrap._gcd_import(name[level:], package, level)
           ^^^^^^^^^^^^^^^^^^^^^^^^^^^^^^^^^^^^^^^^^^^^^^^^^^^^
  File "<frozen importlib._bootstrap>", line 1387, in _gcd_import
  File "<frozen importlib._bootstrap>", line 1360, in _find_and_load
  File "<frozen importlib._bootstrap>", line 1331, in _find_and_load_unlocked
  File "<frozen importlib._bootstrap>", line 935, in _load_unlocked
  File "<frozen importlib._bootstrap_external>", line 995, in exec_module
  File "<frozen importlib._bootstrap>", line 488, in _call_with_frames_removed
  File "/home/oyone/fastapi_project/main.py", line 3, in <module>
    app = create_app()
          ^^^^^^^^^^^^
  File "/home/oyone/fastapi_project/start_files/app.py", line 13, in create_app
    templates = get_templates()
                ^^^^^^^^^^^^^^^
  File "/home/oyone/fastapi_project/start_files/config.py", line 24, in get_templates
    return Jinja2Templates(directory="start_files/templates")
           ^^^^^^^^^^^^^^^^^^^^^^^^^^^^^^^^^^^^^^^^^^^^^^^^^^
  File "/home/oyone/fastapi_project/venv/lib/python3.12/site-packages/starlette/templating.py", line 102, in __init__
    assert jinja2 is not None, "jinja2 must be installed to use Jinja2Templates"
           ^^^^^^^^^^^^^^^^^^
AssertionError: jinja2 must be installed to use Jinja2Templates
[2024-08-22 09:43:56 -0400] [23551] [INFO] Worker exiting (pid: 23551)
[2024-08-22 09:44:08 -0400] [23558] [INFO] Starting gunicorn 23.0.0
[2024-08-22 09:44:08 -0400] [23558] [ERROR] Connection in use: ('0.0.0.0', 5000)
[2024-08-22 09:44:08 -0400] [23558] [ERROR] connection to ('0.0.0.0', 5000) failed: [Errno 98] Address already in use
[2024-08-22 09:44:09 -0400] [23558] [ERROR] Connection in use: ('0.0.0.0', 5000)
[2024-08-22 09:44:09 -0400] [23558] [ERROR] connection to ('0.0.0.0', 5000) failed: [Errno 98] Address already in use
[2024-08-22 09:44:10 -0400] [23558] [ERROR] Connection in use: ('0.0.0.0', 5000)
[2024-08-22 09:44:10 -0400] [23558] [ERROR] connection to ('0.0.0.0', 5000) failed: [Errno 98] Address already in use
[2024-08-22 09:44:11 -0400] [23558] [ERROR] Connection in use: ('0.0.0.0', 5000)
[2024-08-22 09:44:11 -0400] [23558] [ERROR] connection to ('0.0.0.0', 5000) failed: [Errno 98] Address already in use
[2024-08-22 09:44:12 -0400] [23558] [ERROR] Connection in use: ('0.0.0.0', 5000)
[2024-08-22 09:44:12 -0400] [23558] [ERROR] connection to ('0.0.0.0', 5000) failed: [Errno 98] Address already in use
[2024-08-22 09:44:13 -0400] [23558] [ERROR] Can't connect to ('0.0.0.0', 5000)
[2024-08-22 09:45:01 -0400] [23560] [INFO] Starting gunicorn 23.0.0
[2024-08-22 09:45:01 -0400] [23560] [ERROR] Connection in use: ('0.0.0.0', 5000)
[2024-08-22 09:45:01 -0400] [23560] [ERROR] connection to ('0.0.0.0', 5000) failed: [Errno 98] Address already in use
[2024-08-22 09:45:02 -0400] [23560] [ERROR] Connection in use: ('0.0.0.0', 5000)
[2024-08-22 09:45:02 -0400] [23560] [ERROR] connection to ('0.0.0.0', 5000) failed: [Errno 98] Address already in use
[2024-08-22 09:45:03 -0400] [23560] [ERROR] Connection in use: ('0.0.0.0', 5000)
[2024-08-22 09:45:03 -0400] [23560] [ERROR] connection to ('0.0.0.0', 5000) failed: [Errno 98] Address already in use
[2024-08-22 09:45:04 -0400] [23560] [ERROR] Connection in use: ('0.0.0.0', 5000)
[2024-08-22 09:45:04 -0400] [23560] [ERROR] connection to ('0.0.0.0', 5000) failed: [Errno 98] Address already in use
[2024-08-22 09:45:05 -0400] [23560] [ERROR] Connection in use: ('0.0.0.0', 5000)
[2024-08-22 09:45:05 -0400] [23560] [ERROR] connection to ('0.0.0.0', 5000) failed: [Errno 98] Address already in use
[2024-08-22 09:45:06 -0400] [23560] [ERROR] Can't connect to ('0.0.0.0', 5000)
[2024-08-22 09:45:40 -0400] [23568] [INFO] Starting gunicorn 23.0.0
[2024-08-22 09:45:40 -0400] [23568] [ERROR] Connection in use: ('0.0.0.0', 5000)
[2024-08-22 09:45:40 -0400] [23568] [ERROR] connection to ('0.0.0.0', 5000) failed: [Errno 98] Address already in use
[2024-08-22 09:45:41 -0400] [23568] [ERROR] Connection in use: ('0.0.0.0', 5000)
[2024-08-22 09:45:41 -0400] [23568] [ERROR] connection to ('0.0.0.0', 5000) failed: [Errno 98] Address already in use
[2024-08-22 09:45:42 -0400] [23568] [ERROR] Connection in use: ('0.0.0.0', 5000)
[2024-08-22 09:45:42 -0400] [23568] [ERROR] connection to ('0.0.0.0', 5000) failed: [Errno 98] Address already in use
[2024-08-22 09:45:43 -0400] [23568] [ERROR] Connection in use: ('0.0.0.0', 5000)
[2024-08-22 09:45:43 -0400] [23568] [ERROR] connection to ('0.0.0.0', 5000) failed: [Errno 98] Address already in use
[2024-08-22 09:45:44 -0400] [23568] [ERROR] Connection in use: ('0.0.0.0', 5000)
[2024-08-22 09:45:44 -0400] [23568] [ERROR] connection to ('0.0.0.0', 5000) failed: [Errno 98] Address already in use
[2024-08-22 09:45:45 -0400] [23568] [ERROR] Can't connect to ('0.0.0.0', 5000)
[2024-08-22 09:46:59 -0400] [23589] [DEBUG] Current configuration:
  config: gunicorn_config.py
  wsgi_app: None
  bind: ['0.0.0.0:5000']
  backlog: 2048
  workers: 4
  worker_class: uvicorn.workers.UvicornWorker
  threads: 1
  worker_connections: 1000
  max_requests: 0
  max_requests_jitter: 0
  timeout: 30
  graceful_timeout: 30
  keepalive: 2
  limit_request_line: 4094
  limit_request_fields: 100
  limit_request_field_size: 8190
  reload: False
  reload_engine: auto
  reload_extra_files: []
  spew: False
  check_config: False
  print_config: False
  preload_app: False
  sendfile: None
  reuse_port: False
  chdir: /home/oyone/fastapi_project
  daemon: False
  raw_env: []
  pidfile: None
  worker_tmp_dir: None
  user: 1000
  group: 1003
  umask: 0
  initgroups: False
  tmp_upload_dir: None
  secure_scheme_headers: {'X-FORWARDED-PROTOCOL': 'ssl', 'X-FORWARDED-PROTO': 'https', 'X-FORWARDED-SSL': 'on'}
  forwarded_allow_ips: ['127.0.0.1', '::1']
  accesslog: /home/oyone/fastapi_project/logs/access.log
  disable_redirect_access_to_syslog: False
  access_log_format: %(h)s %(l)s %(u)s %(t)s "%(r)s" %(s)s %(b)s "%(f)s" "%(a)s"
  errorlog: /home/oyone/fastapi_project/logs/error.log
  loglevel: debug
  capture_output: False
  logger_class: gunicorn.glogging.Logger
  logconfig: None
  logconfig_dict: {}
  logconfig_json: None
  syslog_addr: udp://localhost:514
  syslog: False
  syslog_prefix: None
  syslog_facility: user
  enable_stdio_inheritance: False
  statsd_host: None
  dogstatsd_tags: 
  statsd_prefix: 
  proc_name: None
  default_proc_name: main:app
  pythonpath: None
  paste: None
  on_starting: <function OnStarting.on_starting at 0xffffb33ec180>
  on_reload: <function OnReload.on_reload at 0xffffb33ec2c0>
  when_ready: <function WhenReady.when_ready at 0xffffb33ec400>
  pre_fork: <function Prefork.pre_fork at 0xffffb33ec5e0>
  post_fork: <function Postfork.post_fork at 0xffffb33ec720>
  post_worker_init: <function PostWorkerInit.post_worker_init at 0xffffb33ec860>
  worker_int: <function WorkerInt.worker_int at 0xffffb33ec9a0>
  worker_abort: <function WorkerAbort.worker_abort at 0xffffb33ecae0>
  pre_exec: <function PreExec.pre_exec at 0xffffb33ecc20>
  pre_request: <function PreRequest.pre_request at 0xffffb33ecd60>
  post_request: <function PostRequest.post_request at 0xffffb33ece00>
  child_exit: <function ChildExit.child_exit at 0xffffb33ecf40>
  worker_exit: <function WorkerExit.worker_exit at 0xffffb33ed080>
  nworkers_changed: <function NumWorkersChanged.nworkers_changed at 0xffffb33ed1c0>
  on_exit: <function OnExit.on_exit at 0xffffb33ed300>
  ssl_context: <function NewSSLContext.ssl_context at 0xffffb33ed4e0>
  proxy_protocol: False
  proxy_allow_ips: ['127.0.0.1', '::1']
  keyfile: None
  certfile: None
  ssl_version: 2
  cert_reqs: 0
  ca_certs: None
  suppress_ragged_eofs: True
  do_handshake_on_connect: False
  ciphers: None
  raw_paste_global_conf: []
  permit_obsolete_folding: False
  strip_header_spaces: False
  permit_unconventional_http_method: False
  permit_unconventional_http_version: False
  casefold_http_method: False
  forwarder_headers: ['SCRIPT_NAME', 'PATH_INFO']
  header_map: drop
[2024-08-22 09:46:59 -0400] [23589] [INFO] Starting gunicorn 23.0.0
[2024-08-22 09:46:59 -0400] [23589] [ERROR] Connection in use: ('0.0.0.0', 5000)
[2024-08-22 09:46:59 -0400] [23589] [ERROR] connection to ('0.0.0.0', 5000) failed: [Errno 98] Address already in use
[2024-08-22 09:46:59 -0400] [23589] [DEBUG] Retrying in 1 second.
[2024-08-22 09:47:00 -0400] [23589] [ERROR] Connection in use: ('0.0.0.0', 5000)
[2024-08-22 09:47:00 -0400] [23589] [ERROR] connection to ('0.0.0.0', 5000) failed: [Errno 98] Address already in use
[2024-08-22 09:47:00 -0400] [23589] [DEBUG] Retrying in 1 second.
[2024-08-22 09:47:01 -0400] [23589] [ERROR] Connection in use: ('0.0.0.0', 5000)
[2024-08-22 09:47:01 -0400] [23589] [ERROR] connection to ('0.0.0.0', 5000) failed: [Errno 98] Address already in use
[2024-08-22 09:47:01 -0400] [23589] [DEBUG] Retrying in 1 second.
[2024-08-22 09:47:02 -0400] [23589] [ERROR] Connection in use: ('0.0.0.0', 5000)
[2024-08-22 09:47:02 -0400] [23589] [ERROR] connection to ('0.0.0.0', 5000) failed: [Errno 98] Address already in use
[2024-08-22 09:47:02 -0400] [23589] [DEBUG] Retrying in 1 second.
[2024-08-22 09:47:03 -0400] [23589] [ERROR] Connection in use: ('0.0.0.0', 5000)
[2024-08-22 09:47:03 -0400] [23589] [ERROR] connection to ('0.0.0.0', 5000) failed: [Errno 98] Address already in use
[2024-08-22 09:47:03 -0400] [23589] [DEBUG] Retrying in 1 second.
[2024-08-22 09:47:04 -0400] [23589] [ERROR] Can't connect to ('0.0.0.0', 5000)
[2024-08-22 09:47:21 -0400] [23591] [DEBUG] Current configuration:
  config: gunicorn_config.py
  wsgi_app: None
  bind: ['0.0.0.0:5000']
  backlog: 2048
  workers: 2
  worker_class: uvicorn.workers.UvicornWorker
  threads: 1
  worker_connections: 1000
  max_requests: 0
  max_requests_jitter: 0
  timeout: 30
  graceful_timeout: 30
  keepalive: 2
  limit_request_line: 4094
  limit_request_fields: 100
  limit_request_field_size: 8190
  reload: False
  reload_engine: auto
  reload_extra_files: []
  spew: False
  check_config: False
  print_config: False
  preload_app: False
  sendfile: None
  reuse_port: False
  chdir: /home/oyone/fastapi_project
  daemon: False
  raw_env: []
  pidfile: None
  worker_tmp_dir: None
  user: 1000
  group: 1003
  umask: 0
  initgroups: False
  tmp_upload_dir: None
  secure_scheme_headers: {'X-FORWARDED-PROTOCOL': 'ssl', 'X-FORWARDED-PROTO': 'https', 'X-FORWARDED-SSL': 'on'}
  forwarded_allow_ips: ['127.0.0.1', '::1']
  accesslog: /home/oyone/fastapi_project/logs/access.log
  disable_redirect_access_to_syslog: False
  access_log_format: %(h)s %(l)s %(u)s %(t)s "%(r)s" %(s)s %(b)s "%(f)s" "%(a)s"
  errorlog: /home/oyone/fastapi_project/logs/error.log
  loglevel: debug
  capture_output: False
  logger_class: gunicorn.glogging.Logger
  logconfig: None
  logconfig_dict: {}
  logconfig_json: None
  syslog_addr: udp://localhost:514
  syslog: False
  syslog_prefix: None
  syslog_facility: user
  enable_stdio_inheritance: False
  statsd_host: None
  dogstatsd_tags: 
  statsd_prefix: 
  proc_name: None
  default_proc_name: main:app
  pythonpath: None
  paste: None
  on_starting: <function OnStarting.on_starting at 0xffffb293c180>
  on_reload: <function OnReload.on_reload at 0xffffb293c2c0>
  when_ready: <function WhenReady.when_ready at 0xffffb293c400>
  pre_fork: <function Prefork.pre_fork at 0xffffb293c5e0>
  post_fork: <function Postfork.post_fork at 0xffffb293c720>
  post_worker_init: <function PostWorkerInit.post_worker_init at 0xffffb293c860>
  worker_int: <function WorkerInt.worker_int at 0xffffb293c9a0>
  worker_abort: <function WorkerAbort.worker_abort at 0xffffb293cae0>
  pre_exec: <function PreExec.pre_exec at 0xffffb293cc20>
  pre_request: <function PreRequest.pre_request at 0xffffb293cd60>
  post_request: <function PostRequest.post_request at 0xffffb293ce00>
  child_exit: <function ChildExit.child_exit at 0xffffb293cf40>
  worker_exit: <function WorkerExit.worker_exit at 0xffffb293d080>
  nworkers_changed: <function NumWorkersChanged.nworkers_changed at 0xffffb293d1c0>
  on_exit: <function OnExit.on_exit at 0xffffb293d300>
  ssl_context: <function NewSSLContext.ssl_context at 0xffffb293d4e0>
  proxy_protocol: False
  proxy_allow_ips: ['127.0.0.1', '::1']
  keyfile: None
  certfile: None
  ssl_version: 2
  cert_reqs: 0
  ca_certs: None
  suppress_ragged_eofs: True
  do_handshake_on_connect: False
  ciphers: None
  raw_paste_global_conf: []
  permit_obsolete_folding: False
  strip_header_spaces: False
  permit_unconventional_http_method: False
  permit_unconventional_http_version: False
  casefold_http_method: False
  forwarder_headers: ['SCRIPT_NAME', 'PATH_INFO']
  header_map: drop
[2024-08-22 09:47:21 -0400] [23591] [INFO] Starting gunicorn 23.0.0
[2024-08-22 09:47:21 -0400] [23591] [ERROR] Connection in use: ('0.0.0.0', 5000)
[2024-08-22 09:47:21 -0400] [23591] [ERROR] connection to ('0.0.0.0', 5000) failed: [Errno 98] Address already in use
[2024-08-22 09:47:21 -0400] [23591] [DEBUG] Retrying in 1 second.
[2024-08-22 09:47:22 -0400] [23591] [ERROR] Connection in use: ('0.0.0.0', 5000)
[2024-08-22 09:47:22 -0400] [23591] [ERROR] connection to ('0.0.0.0', 5000) failed: [Errno 98] Address already in use
[2024-08-22 09:47:22 -0400] [23591] [DEBUG] Retrying in 1 second.
[2024-08-22 09:47:23 -0400] [23591] [ERROR] Connection in use: ('0.0.0.0', 5000)
[2024-08-22 09:47:23 -0400] [23591] [ERROR] connection to ('0.0.0.0', 5000) failed: [Errno 98] Address already in use
[2024-08-22 09:47:23 -0400] [23591] [DEBUG] Retrying in 1 second.
[2024-08-22 09:47:24 -0400] [23591] [ERROR] Connection in use: ('0.0.0.0', 5000)
[2024-08-22 09:47:24 -0400] [23591] [ERROR] connection to ('0.0.0.0', 5000) failed: [Errno 98] Address already in use
[2024-08-22 09:47:24 -0400] [23591] [DEBUG] Retrying in 1 second.
[2024-08-22 09:47:25 -0400] [23591] [ERROR] Connection in use: ('0.0.0.0', 5000)
[2024-08-22 09:47:25 -0400] [23591] [ERROR] connection to ('0.0.0.0', 5000) failed: [Errno 98] Address already in use
[2024-08-22 09:47:25 -0400] [23591] [DEBUG] Retrying in 1 second.
[2024-08-22 09:47:26 -0400] [23591] [ERROR] Can't connect to ('0.0.0.0', 5000)
[2024-08-22 09:47:55 -0400] [23596] [DEBUG] Current configuration:
  config: gunicorn_config.py
  wsgi_app: None
  bind: ['127.0.0.0.1:5000']
  backlog: 2048
  workers: 2
  worker_class: uvicorn.workers.UvicornWorker
  threads: 1
  worker_connections: 1000
  max_requests: 0
  max_requests_jitter: 0
  timeout: 30
  graceful_timeout: 30
  keepalive: 2
  limit_request_line: 4094
  limit_request_fields: 100
  limit_request_field_size: 8190
  reload: False
  reload_engine: auto
  reload_extra_files: []
  spew: False
  check_config: False
  print_config: False
  preload_app: False
  sendfile: None
  reuse_port: False
  chdir: /home/oyone/fastapi_project
  daemon: False
  raw_env: []
  pidfile: None
  worker_tmp_dir: None
  user: 1000
  group: 1003
  umask: 0
  initgroups: False
  tmp_upload_dir: None
  secure_scheme_headers: {'X-FORWARDED-PROTOCOL': 'ssl', 'X-FORWARDED-PROTO': 'https', 'X-FORWARDED-SSL': 'on'}
  forwarded_allow_ips: ['127.0.0.1', '::1']
  accesslog: /home/oyone/fastapi_project/logs/access.log
  disable_redirect_access_to_syslog: False
  access_log_format: %(h)s %(l)s %(u)s %(t)s "%(r)s" %(s)s %(b)s "%(f)s" "%(a)s"
  errorlog: /home/oyone/fastapi_project/logs/error.log
  loglevel: debug
  capture_output: False
  logger_class: gunicorn.glogging.Logger
  logconfig: None
  logconfig_dict: {}
  logconfig_json: None
  syslog_addr: udp://localhost:514
  syslog: False
  syslog_prefix: None
  syslog_facility: user
  enable_stdio_inheritance: False
  statsd_host: None
  dogstatsd_tags: 
  statsd_prefix: 
  proc_name: None
  default_proc_name: main:app
  pythonpath: None
  paste: None
  on_starting: <function OnStarting.on_starting at 0xffff91d6c180>
  on_reload: <function OnReload.on_reload at 0xffff91d6c2c0>
  when_ready: <function WhenReady.when_ready at 0xffff91d6c400>
  pre_fork: <function Prefork.pre_fork at 0xffff91d6c5e0>
  post_fork: <function Postfork.post_fork at 0xffff91d6c720>
  post_worker_init: <function PostWorkerInit.post_worker_init at 0xffff91d6c860>
  worker_int: <function WorkerInt.worker_int at 0xffff91d6c9a0>
  worker_abort: <function WorkerAbort.worker_abort at 0xffff91d6cae0>
  pre_exec: <function PreExec.pre_exec at 0xffff91d6cc20>
  pre_request: <function PreRequest.pre_request at 0xffff91d6cd60>
  post_request: <function PostRequest.post_request at 0xffff91d6ce00>
  child_exit: <function ChildExit.child_exit at 0xffff91d6cf40>
  worker_exit: <function WorkerExit.worker_exit at 0xffff91d6d080>
  nworkers_changed: <function NumWorkersChanged.nworkers_changed at 0xffff91d6d1c0>
  on_exit: <function OnExit.on_exit at 0xffff91d6d300>
  ssl_context: <function NewSSLContext.ssl_context at 0xffff91d6d4e0>
  proxy_protocol: False
  proxy_allow_ips: ['127.0.0.1', '::1']
  keyfile: None
  certfile: None
  ssl_version: 2
  cert_reqs: 0
  ca_certs: None
  suppress_ragged_eofs: True
  do_handshake_on_connect: False
  ciphers: None
  raw_paste_global_conf: []
  permit_obsolete_folding: False
  strip_header_spaces: False
  permit_unconventional_http_method: False
  permit_unconventional_http_version: False
  casefold_http_method: False
  forwarder_headers: ['SCRIPT_NAME', 'PATH_INFO']
  header_map: drop
[2024-08-22 09:47:55 -0400] [23596] [INFO] Starting gunicorn 23.0.0
[2024-08-22 09:47:55 -0400] [23596] [ERROR] connection to ('127.0.0.0.1', 5000) failed: [Errno -2] Name or service not known
[2024-08-22 09:47:55 -0400] [23596] [DEBUG] Retrying in 1 second.
[2024-08-22 09:47:56 -0400] [23596] [ERROR] connection to ('127.0.0.0.1', 5000) failed: [Errno -2] Name or service not known
[2024-08-22 09:47:56 -0400] [23596] [DEBUG] Retrying in 1 second.
[2024-08-22 09:47:57 -0400] [23596] [ERROR] connection to ('127.0.0.0.1', 5000) failed: [Errno -2] Name or service not known
[2024-08-22 09:47:57 -0400] [23596] [DEBUG] Retrying in 1 second.
[2024-08-22 09:47:58 -0400] [23596] [ERROR] connection to ('127.0.0.0.1', 5000) failed: [Errno -2] Name or service not known
[2024-08-22 09:47:58 -0400] [23596] [DEBUG] Retrying in 1 second.
[2024-08-22 09:47:59 -0400] [23596] [ERROR] connection to ('127.0.0.0.1', 5000) failed: [Errno -2] Name or service not known
[2024-08-22 09:47:59 -0400] [23596] [DEBUG] Retrying in 1 second.
[2024-08-22 09:48:00 -0400] [23596] [ERROR] Can't connect to ('127.0.0.0.1', 5000)
